Exception in thread Thread-15:
Traceback (most recent call last):
  File "/usr/lib/python3.7/threading.py", line 926, in _bootstrap_inner
    self.run()
  File "/usr/lib/python3.7/threading.py", line 870, in run
    self._target(*self._args, **self._kwargs)
  File "/usr/local/lib/python3.7/dist-packages/wandb/sdk/wandb_run.py", line 180, in check_network_status
    status_response = self._interface.communicate_network_status()
  File "/usr/local/lib/python3.7/dist-packages/wandb/sdk/interface/interface.py", line 749, in communicate_network_status
    resp = self._communicate(req, timeout=timeout, local=True)
  File "/usr/local/lib/python3.7/dist-packages/wandb/sdk/interface/interface.py", line 539, in _communicate
    return self._communicate_async(rec, local=local).get(timeout=timeout)
  File "/usr/local/lib/python3.7/dist-packages/wandb/sdk/interface/interface.py", line 544, in _communicate_async
    raise Exception("The wandb backend process has shutdown")
Exception: The wandb backend process has shutdown
Exception in thread Thread-14:
Traceback (most recent call last):
  File "/usr/lib/python3.7/threading.py", line 926, in _bootstrap_inner
    self.run()
  File "/usr/lib/python3.7/threading.py", line 870, in run
    self._target(*self._args, **self._kwargs)
  File "/usr/local/lib/python3.7/dist-packages/wandb/sdk/wandb_run.py", line 198, in check_status
    status_response = self._interface.communicate_stop_status()
  File "/usr/local/lib/python3.7/dist-packages/wandb/sdk/interface/interface.py", line 737, in communicate_stop_status
    resp = self._communicate(req, timeout=timeout, local=True)
  File "/usr/local/lib/python3.7/dist-packages/wandb/sdk/interface/interface.py", line 539, in _communicate
    return self._communicate_async(rec, local=local).get(timeout=timeout)
  File "/usr/local/lib/python3.7/dist-packages/wandb/sdk/interface/interface.py", line 544, in _communicate_async
    raise Exception("The wandb backend process has shutdown")
Exception: The wandb backend process has shutdown
Drive already mounted at /content/drive; to attempt to forcibly remount, call drive.mount("/content/drive", force_remount=True).
Error in callback <bound method _WandbInit._resume_backend of <wandb.sdk.wandb_init._WandbInit object at 0x7f0faf281a90>> (for pre_run_cell):